Workbook
Name Slicer_Channel: #N/A
Name Slicer_Country: #N/A
Name Slicer_months: #N/A
Name Slicer_ProductCategory: #N/A
Name Slicer_Region: #N/A
Name Slicer_Salesperson: #N/A

Sheet original_data
A1: OrderID | B1: OrderDate | C1: RequiredDate | D1: Region | E1: Country | F1: City | G1: CustomerSegment | H1: Channel | I1: Salesperson | J1: ProductCategory | K1: SKU | L1: UnitCost | M1: UnitPrice | N1: DiscountPct | O1: Quantity
A2: ORD-2024-275203 | B2: 45362 | C2: 45388 | D2: Africa | E2: Kenya | F2: Kisumu | G2: Corporate | H2: Retail | I2: C. Otieno | J2: Components | K2: CMP-8270 | L2: 279.24 | M2: 608.9 | N2: 0.112 | O2: 9
A3: ORD-2024-358795 | B3: 45588 | C3: 45587 | D3: Africa | E3: Nigeria | F3: Port Harcourt | G3: Education | H3: Online | I3: J. Njeri | J3: Printers | K3: PRN-9322 | L3: 1084.39 | M3: 759.33 | N3: 0.237 | O3: 31
A4: ORD-2023-373538 | B4: 44985 | C4: 45010 | D4: Africa | E4: Kenya | F4: Nairobi | G4: Corporate | H4: Retail | I4: I. Johnson | J4: Networking | K4: NET-9666 | L4: 1460.76 | M4: -30.66 | N4: 0.131 | O4: 12
A5: ORD-2025-168148 | B5: 45745 | C5: 45749 | D5: Africa | E5: Nigeria | F5: Lagos | G5: Non-Profit | H5: Marketplace | I5: G. Dubois | J5: Phones | K5: PHN-4556 | L5: 259.93 | M5: 255.94 | N5: 0.072 | O5: 22
A6: ORD-2023-824839 | B6: 45266 | C6: 45291 | D6: Asia | E6: Japan | F6: Osaka | G6: Consumer | H6: Retail | I6: L. Okafor | J6: Printers | K6: PRN-8041 | L6: 663.03 | M6: 813.51 | N6: 0.102 | O6: 15
A7: ORD-2023-723587 | B7: 44928 | C7: 44931 | D7: Americas | E7: Canada | F7: Toronto | G7: Corporate | H7: Distributor | I7: B. Chen | J7: Laptops | K7: LAP-8555 | L7: 315.87 | M7: 591.68 | N7: 0 | O7: 7
A8: ORD-2024-336584 | B8: 45653 | C8: 45671 | D8: Asia | E8: India | F8: Bengaluru | G8: Small Business | H8: Marketplace | I8: E. Garcia | J8: Monitors | K8: MON-8629 | L8: 586.07 | M8: 845.97 | N8: 0.147 | O8: 4
A9: ORD-2023-112666 | B9: 44941 | C9: 44939 | D9: Africa | E9: Nigeria | F9: Abuja | G9: Education | H9: Online | I9: O. Wang | J9: Printers | K9: PRN-6276 | L9: 28.38 | M9: 47.22 | N9: 0.194 | O9: 18
A10: ORD-2024-589570 | B10: 45416 | C10: 45441 | D10: Africa | E10: Nigeria | F10: Abuja | G10: Non-Profit | H10: Marketplace | I10: O. Wang | J10: Monitors | K10: MON-6892 | L10: 1295.34 | M10: 2530.81 | N10: 0.031 | O10: 6
A11: ORD-2025-997421 | B11: 45798 | C11: 45817 | D11: Americas | E11: Brazil | F11: São Paulo | G11: Non-Profit | H11: Online | I11: A. Patel | J11: Components | K11: CMP-3731 | L11: 1331.38 | M11: 2309.56 | N11: 0.149 | O11: 31
A12: ORD-2024-210687 | B12: 45319 | C12: 45331 | D12: Europe | E12: Germany | F12: Berlin | G12: Corporate | H12: Online | I12: G. Dubois | J12: Accessories | K12: ACC-7938 | L12: 644.17 | M12: 700.12 | N12: 0.006 | O12: 23
A13: ORD-2025-515515 | B13: 45660 | C13: 45680 | D13: Asia | E13: Japan | F13: Osaka | G13: Corporate | H13: Distributor | I13: F. Müller | J13: Phones | K13: PHN-7019 | L13: 908.6 | M13: 691.37 | N13: 0.25 | O13: 20
... A34: ORD-2025-474710 | B34: 45862 | C34: 45875 | D34: Africa | E34: South Africa | F34: Johannesburg | G34: Education | H34: Marketplace | I34: D. Smith | J34: Networking | K34: NET-7966 | L34: 1463.9 | M34: 2633.02 | N34: 0.084 | O34: 4
A35: ORD-2024-629525 | B35: 45400 | C35: 45420 | D35: Europe | E35: United Kingdom | F35: London | G35: Non-Profit | I35: D. Smith | J35: Laptops | K35: LAP-9932 | L35: 645.33 | M35: 1321.85 | N35: 0 | O35: 10
A36: ORD-2024-167215 | B36: 45527 | C36: 45525 | D36: Africa | E36: South Africa | F36: Johannesburg | G36: Education | H36: Retail | I36: E. Garcia | J36: Components | K36: CMP-1559 | L36: 1432.52 | M36: 3036.87 | N36: 0 | O36: 9
A37: ORD-2023-864121 | B37: 45012 | C37: 45038 | D37: Asia | E37: India | F37: Delhi | G37: Non-Profit | H37: Marketplace | I37: J. Njeri | J37: Printers | K37: PRN-4506 | L37: 178.53 | M37: 199.37 | N37: 0.101 | O37: 37
A38: ORD-2024-692673 | B38: 45358 | C38: 45376 | D38: Europe | E38: Germany | F38: Munich | G38: Corporate | H38: Online | I38: B. Chen | J38: Components | K38: CMP-7617 | L38: 712.84 | M38: 927.51 | N38: 0.243 | O38: 27
A39: ORD-2025-718992 | B39: 45832 | C39: 45848 | D39: Asia | E39: China | F39: Shanghai | G39: Enterprise | H39: Direct | I39: N. Brown | J39: Components | K39: CMP-8390 | L39: 757.19 | M39: 1735.41 | N39: 0.136 | O39: 8
A40: ORD-2024-599522 | B40: 45401 | C40: 45418 | D40: Africa | E40: Nigeria | F40: Port Harcourt | G40: Non-Profit | H40: Online | I40: A. Patel | J40: Printers | K40: PRN-7303 | L40: 865.33 | M40: 1395.64 | N40: 0.175 | O40: 13
A41: ORD-2023-651638 | B41: 45094 | C41: 45101 | D41: Americas | E41: USA | F41: San Francisco | G41: Corporate | H41: Retail | I41: I. Johnson | J41: Printers | K41: PRN-6536 | L41: 313.99 | M41: 454.42 | N41: 0.129 | O41: 9
A42: ORD-2024-635626 | B42: 45531 | C42: 45554 | D42: Europe | E42: Germany | F42: Berlin | G42: Small Business | H42: Direct | I42: D. Smith | J42: Monitors | K42: MON-9967 | L42: 1024.01 | M42: 1580.97 | N42: 0.037 | O42: 27
A43: ORD-2024-296582 | B43: 45302 | C43: 45324 | D43: Africa | E43: South Africa | F43: Durban | G43: Consumer | H43: Online | I43: K. Singh | J43: Networking | K43: NET-1412 | L43: 1206.2 | M43: 1759.79 | N43: 0 | O43: 6
A44: ORD-2024-998320 | B44: 45590 | C44: 45610 | D44: Africa | E44: Kenya | F44: Mombasa | G44: Corporate | H44: Direct | I44: H. Kim | J44: Printers | K44: PRN-3143 | L44: 1396.48 | M44: 3204.5 | N44: 0.318 | O44: 14
A45: ORD-2025-820255 | B45: 45806 | C45: 45828 | D45: Europe | E45: Germany | F45: Berlin | G45: Corporate | H45: Direct | I45: A. Patel | J45: Printers | K45: PRN-9787 | L45: 483.47 | M45: 1135.43 | N45: 0.146 | O45: 11
A46: ORD-2024-389336 | B46: 45432 | C46: 45445 | D46: Americas | E46: Canada | F46: Vancouver | G46: Enterprise | H46: Marketplace | I46: K. Singh | J46: Components | K46: CMP-5946 | L46: 675.43 | M46: 996.36 | N46: 0.182 | O46: 22
A47: ORD-2023-308124 | B47: 45035 | C47: 45046 | D47: Asia | E47: India | F47: Delhi | G47: Small Business | H47: Retail | I47: A. Patel | J47: Networking | K47: NET-2062 | L47: 826.55 | M47: 1397.05 | N47: 0.169 | O47: 28
... A77: ORD-2023-722117 | B77: 45187 | C77: 45207 | D77: Asia | E77: India | F77: Delhi | G77: Small Business | H77: Direct | I77: B. Chen | J77: Components | K77: CMP-1009 | L77: 825.64 | M77: 1108.43 | N77: 0.114 | O77: 7
A78: ORD-2024-446699 | B78: 45532 | C78: 45560 | D78: Americas | E78: Brazil | F78: Rio de Janeiro | G78: Non-Profit | H78: Online | J78: Accessories | K78: ACC-4490 | L78: 1394.65 | M78: 3144.1 | N78: 0.134 | O78: 13
A79: ORD-2024-451005 | B79: 45473 | C79: 45471 | D79: Americas | E79: Brazil | F79: Rio de Janeiro | G79: Small Business | H79: Direct | I79: L. Okafor | J79: Accessories | K79: ACC-9162 | L79: 1112.98 | M79: 2095.73 | N79: 0.072 | O79: 17
A80: ORD-2023-290279 | B80: 45091 | C80: 45093 | D80: Europe | E80: United Kingdom | F80: Manchester | G80: Non-Profit | H80: Direct | I80: K. Singh | J80: Components | K80: CMP-5820 | L80: 357.36 | M80: 703.62 | N80: 0.257 | O80: 20
A81: ORD-2024-192263 | B81: 45617 | C81: 45647 | D81: Europe | E81: France | F81: Marseille | G81: Small Business | H81: Direct | I81: I. Johnson | J81: Monitors | K81: MON-7943 | L81: 1122.68 | M81: 1997.19 | N81: 0.186 | O81: 3
A82: ORD-2023-159379 | B82: 44965 | C82: 44968 | D82: Africa | E82: South Africa | F82: Cape Town | G82: Corporate | H82: Direct | I82: M. Rossi | J82: Networking | K82: NET-5018 | L82: 1410.05 | M82: 2763.95 | N82: 0.161 | O82: 26
A83: ORD-2023-343322 | B83: 45157 | C83: 45181 | D83: Americas | E83: Canada | F83: Vancouver | G83: Enterprise | H83: Retail | I83: I. Johnson | J83: Printers | K83: PRN-9669 | L83: 1183.95 | M83: 1503.53 | N83: 0.241 | O83: 16
A84: ORD-2025-114382 | B84: 45791 | C84: 45801 | D84: Europe | E84: France | F84: Paris | G84: Small Business | H84: Marketplace | I84: K. Singh | J84: Components | K84: CMP-2865 | L84: 170.39 | M84: 388.04 | N84: 0.084 | O84: 15
A85: ORD-2025-488349 | B85: 45770 | C85: 45769 | D85: Americas | E85: USA | F85: San Francisco | G85: Non-Profit | H85: Distributor | I85: D. Smith | J85: Monitors | K85: MON-3371 | L85: 23.24 | M85: 44.57 | N85: 0.215 | O85: 15
A86: ORD-2025-330203 | B86: 45741 | C86: 45764 | D86: Europe | E86: United Kingdom | F86: London | G86: Consumer | H86: Retail | I86: H. Kim | J86: Networking | K86: NET-7166 | L86: 1421.19 | M86: 1808.26 | N86: 0.104 | O86: 13
A87: ORD-2023-841426 | B87: 45282 | C87: 45283 | D87: Africa | E87: South Africa | F87: Cape Town | G87: Non-Profit | H87: Marketplace | I87: D. Smith | J87: Components | K87: CMP-4531 | L87: 1186.18 | M87: 1285.09 | N87: 0.07 | O87: 11
A88: ORD-2024-594592 | B88: 45388 | C88: 45407 | D88: Asia | E88: China | F88: Shanghai | G88: Corporate | H88: Retail | I88: K. Singh | J88: Components | K88: CMP-8196 | L88: 1366.48 | M88: 1678.14 | N88: 0.154 | O88: 10
A89: ORD-2025-863978 | B89: 45876 | C89: 45888 | D89: Africa | E89: Kenya | F89: Nakuru | G89: Corporate | I89: M. Rossi | J89: Components | K89: CMP-2854 | L89: 601.51 | M89: 679.35 | N89: 0.188 | O89: 3
...

Sheet ReadMe
A1: Sales Operations & Analytics
A4: 1. DATA ISSUES FOUND (in original_data, 632 rows)
A5: • Missing values: 8 blank City, 8 blank Channel, 8 blank Salesperson.
A6: • RequiredDate earlier than OrderDate on some rows (negative lead time).
A7: • Discounts above the 30% policy cap (flagged); largest observed 56.5%.
A8: • Cost > Price on some lines, producing negative gross profit.
A9: • Mixed/unstandardised dimensions requiring Month / Quarter / Price-band derivation.
A11: 2. CLEANING RULES APPLIED (see clean_data / Table1)
A12: • Duplicates: rows treated as unique by OrderID; no exact full-row duplicates were found, so none removed.
A13: • Data types: OrderDate / RequiredDate stored as dates; cost, price, qty, discount as numbers.
A14: • Missing City -> imputed with the most common City for that Country (mode).
A15: • Missing Channel -> imputed with the most common Channel for that Country (mode).
... A47: • No hard-coded totals: every measure is a live Excel formula or PivotTable.

Sheet Brief
A1: Assignment
A2: Excel Mastery Assignment: Sales Operations & Analytics
A4: Overview:
A5: You are an analyst for a multi-regional electronics distributor. The 'Data' sheet contains 632 rows and 15 columns of transactional data with intentional data-quality issues.
A6: Your job is to clean, enrich, analyze, and present insights via a dynamic dashboard.
A8: Part A — Data Cleaning & Preparation:
A9: 1) Create a staging table where you:
A10: • Remove exact duplicate rows (define and document your duplicate criteria).
A11: • Fix data types (dates as Dates, numeric fields as numbers).
A12: • Handle missing values for City, Salesperson, and Channel using reasonable business logic (document your approach).
A13: • Flag and correct suspicious UnitPrice values (e.g., negative prices) and discounts (e.g., > 30%).
A14: • Ensure RequiredDate is not earlier than OrderDate; where it is, impute a corrected RequiredDate (explain your rule).
... A67: 15) Ensure your dashboard responds to slicers without broken references.

Sheet clean_data
A1: OrderID | B1: short_order_id | C1: order_year | D1: first_time_orders | E1: Cohort | F1: OrderDate | G1: MMM-YYYY | H1: months | I1: quarters | J1: lead_time | K1: adj_lead_time | L1: lead_proxy | M1: RequiredDate | N1: adj_required_date | O1: Region | P1: Country | Q1: City | R1: CustomerSegment | S1: Channel | T1: Salesperson | U1: ProductCategory | V1: SKU | W1: UnitCost | X1: adj_unit_cost | Y1: UnitPrice | Z1: price_band | AA1: DiscountPct | AB1: cap_adjusted_discount | AC1: discount>30% | AD1: Quantity | AE1: scenario_quantity | AF1: cost_of_goods | AG1: Category_revenue | AH1: Cumulative_revenue | AI1: cumulative_pct | AJ1: ABC | AK1: Scenario_unit_cost | AL1: scenario_revenue | AM1: gross_revenue | AN1: gross_profit | AO1: scenario_profit | AP1: Margin %
A2: ORD-2023-960380 | B2: =_xlfn.TEXTAFTER(Table1[[#This Row],[OrderID]],"-",2) -> 960380 | C2: =YEAR(Table1[[#This Row],[OrderDate]]) -> 2023 | D2: =_xlfn.MINIFS(F:F,P:P,Table1[[#This Row],[Country]]) -> 44941 | E2: =DATEDIF(Table1[[#This Row],[first_time_orders]],Table1[[#This Row],[OrderDate]],"m") -> 0 | F2: 44968 | G2: =TEXT(Table1[[#This Row],[OrderDate]],"MMM-YYYY") -> Feb-2023 | H2: =MONTH(Table1[[#This Row],[OrderDate]]) -> 2 | I2: ="Q"&ROUNDUP(Table1[[#This Row],[months]]/3,0)&"-"&Table1[[#This Row],[order_year]] -> Q1-2023 | J2: =Table1[[#This Row],[RequiredDate]]-Table1[[#This Row],[OrderDate]] -> 1 | K2: =IF(Table1[[#This Row],[lead_time]]<0,MEDIAN(J:J),Table1[[#This Row],[lead_time]]) -> 1 | L2: =IF(Table1[[#This Row],[adj_lead_time]]<=7,1,0) -> 1 | M2: 44969 | N2: =IF(Table1[[#This Row],[lead_time]]<0,(Table1[[#This Row],[OrderDate]]+Table1[[#This Row],[adj_lead_time]]),Table1[[#This Row],[RequiredDate]]) -> 44969 | O2: Africa | P2: Nigeria | Q2: Port Harcourt | R2: Non-Profit | S2: Direct | T2: D. Smith | U2: Accessories | V2: ACC-8242 | W2: 944.61 | X2: =Table1[[#This Row],[UnitCost]]*(1+'scenario modeling'!$B$3) -> 1039.071 | Y2: 839.04 | Z2: =IF(Table1[[#This Row],[UnitPrice]]<=Quantiles!$B$2,Quantiles!$A$2,IF(Table1[[#This Row],[UnitPrice]]<=Quantiles!$B$3,Quantiles!$A$3,Quantiles!$A$4)) -> Medium | AA2: 0.059 | AB2: =MIN(Table1[[#This Row],[DiscountPct]],'scenario modeling'!$B$2) -> 0.059 | AC2: =IF(Table1[[#This Row],[DiscountPct]]>0.3, ">0.3","") | AD2: 6 | AE2: =Table1[[#This Row],[Quantity]]*(1+'scenario modeling'!$B$4) -> 7.2 | AF2: =Table1[[#This Row],[UnitCost]]*Table1[[#This Row],[Quantity]] -> 5667.66 | AG2: =SUMIF($U:U,Table1[[#This Row],[ProductCategory]],$AM:AM) -> 1331102.9 | AH2: =SUMIFS($AM$2:AM2,$U$2:U2,U2) -> 4737.2198 | AI2: =Table1[[#This Row],[Cumulative_revenue]]/Table1[[#This Row],[Category_revenue]] -> 0.0035588681 | AJ2: =IF(Table1[[#This Row],[cumulative_pct]]<=0.8,"A",IF(Table1[[#This Row],[cumulative_pct]]<=0.95,"B","C")) -> A | AK2: =Table1[[#This Row],[adj_unit_cost]]*Table1[[#This Row],[scenario_quantity]] -> 7481.3112 | AL2: =Table1[[#This Row],[UnitPrice]]*Table1[[#This Row],[scenario_quantity]]*(1-Table1[[#This Row],[cap_adjusted_discount]]) -> 5684.6638 | AM2: =Table1[[#This Row],[UnitPrice]]*Table1[[#This Row],[Quantity]]*(1-Table1[[#This Row],[DiscountPct]]) -> 4737.2198 | AN2: =Table1[[#This Row],[gross_revenue]]-Table1[[#This Row],[cost_of_goods]] -> -930.44016 | AO2: =Table1[[#This Row],[scenario_revenue]]-Table1[[#This Row],[Scenario_unit_cost]] -> -1796.6474 | AP2: =IF(Table1[[#This Row],[gross_revenue]]=0,0,Table1[[#This Row],[gross_profit]]/Table1[[#This Row],[gross_revenue]]) -> -0.19641059
A3: ORD-2023-521818 | B3: =_xlfn.TEXTAFTER(Table1[[#This Row],[OrderID]],"-",2) -> 521818 | C3: =YEAR(Table1[[#This Row],[OrderDate]]) -> 2023 | D3: =_xlfn.MINIFS(F:F,P:P,Table1[[#This Row],[Country]]) -> 44955 | E3: =DATEDIF(Table1[[#This Row],[first_time_orders]],Table1[[#This Row],[OrderDate]],"m") -> 0 | F3: 44955 | G3: =TEXT(Table1[[#This Row],[OrderDate]],"MMM-YYYY") -> Jan-2023 | H3: =MONTH(Table1[[#This Row],[OrderDate]]) -> 1 | I3: ="Q"&ROUNDUP(Table1[[#This Row],[months]]/3,0)&"-"&Table1[[#This Row],[order_year]] -> Q1-2023 | J3: =Table1[[#This Row],[RequiredDate]]-Table1[[#This Row],[OrderDate]] -> 30 | K3: =IF(Table1[[#This Row],[lead_time]]<0,MEDIAN(J:J),Table1[[#This Row],[lead_time]]) -> 30 | L3: =IF(Table1[[#This Row],[adj_lead_time]]<=7,1,0) -> 0 | M3: 44985 | N3: =IF(Table1[[#This Row],[lead_time]]<0,(Table1[[#This Row],[OrderDate]]+Table1[[#This Row],[adj_lead_time]]),Table1[[#This Row],[RequiredDate]]) -> 44985 | O3: Asia | P3: India | Q3: Bengaluru | R3: Non-Profit | S3: Retail | T3: B. Chen | U3: Accessories | V3: ACC-4631 | W3: 1262.1 | X3: =Table1[[#This Row],[UnitCost]]*(1+'scenario modeling'!$B$3) -> 1388.31 | Y3: 1395.53 | Z3: =IF(Table1[[#This Row],[UnitPrice]]<=Quantiles!$B$2,Quantiles!$A$2,IF(Table1[[#This Row],[UnitPrice]]<=Quantiles!$B$3,Quantiles!$A$3,Quantiles!$A$4)) -> Medium | AA3: 0.233 | AB3: =MIN(Table1[[#This Row],[DiscountPct]],'scenario modeling'!$B$2) -> 0.1 | AC3: =IF(Table1[[#This Row],[DiscountPct]]>0.3, ">0.3","") | AD3: 25 | AE3: =Table1[[#This Row],[Quantity]]*(1+'scenario modeling'!$B$4) -> 30 | AF3: =Table1[[#This Row],[UnitCost]]*Table1[[#This Row],[Quantity]] -> 31552.5 | AG3: =SUMIF($U:U,Table1[[#This Row],[ProductCategory]],$AM:AM) -> 1331102.9 | AH3: =SUMIFS($AM$2:AM3,$U$2:U3,U3) -> 31496.508 | AI3: =Table1[[#This Row],[Cumulative_revenue]]/Table1[[#This Row],[Category_revenue]] -> 0.023661962 | AJ3: =IF(Table1[[#This Row],[cumulative_pct]]<=0.8,"A",IF(Table1[[#This Row],[cumulative_pct]]<=0.95,"B","C")) -> A | AK3: =Table1[[#This Row],[adj_unit_cost]]*Table1[[#This Row],[scenario_quantity]] -> 41649.3 | AL3: =Table1[[#This Row],[UnitPrice]]*Table1[[#This Row],[scenario_quantity]]*(1-Table1[[#This Row],[cap_adjusted_discount]]) -> 37679.31 | AM3: =Table1[[#This Row],[UnitPrice]]*Table1[[#This Row],[Quantity]]*(1-Table1[[#This Row],[DiscountPct]]) -> 26759.288 | AN3: =Table1[[#This Row],[gross_revenue]]-Table1[[#This Row],[cost_of_goods]] -> -4793.2122 | AO3: =Table1[[#This Row],[scenario_revenue]]-Table1[[#This Row],[Scenario_unit_cost]] -> -3969.99 | AP3: =IF(Table1[[#This Row],[gross_revenue]]=0,0,Table1[[#This Row],[gross_profit]]/Table1[[#This Row],[gross_revenue]]) -> -0.17912331
A4: ORD-2023-780206 | B4: =_xlfn.TEXTAFTER(Table1[[#This Row],[OrderID]],"-",2) -> 780206 | C4: =YEAR(Table1[[#This Row],[OrderDate]]) -> 2023 | D4: =_xlfn.MINIFS(F:F,P:P,Table1[[#This Row],[Country]]) -> 44945 | E4: =DATEDIF(Table1[[#This Row],[first_time_orders]],Table1[[#This Row],[OrderDate]],"m") -> 0 | F4: 44945 | G4: =TEXT(Table1[[#This Row],[OrderDate]],"MMM-YYYY") -> Jan-2023 | H4: =MONTH(Table1[[#This Row],[OrderDate]]) -> 1 | I4: ="Q"&ROUNDUP(Table1[[#This Row],[months]]/3,0)&"-"&Table1[[#This Row],[order_year]] -> Q1-2023 | J4: =Table1[[#This Row],[RequiredDate]]-Table1[[#This Row],[OrderDate]] -> 15 | K4: =IF(Table1[[#This Row],[lead_time]]<0,MEDIAN(J:J),Table1[[#This Row],[lead_time]]) -> 15 | L4: =IF(Table1[[#This Row],[adj_lead_time]]<=7,1,0) -> 0 | M4: 44960 | N4: =IF(Table1[[#This Row],[lead_time]]<0,(Table1[[#This Row],[OrderDate]]+Table1[[#This Row],[adj_lead_time]]),Table1[[#This Row],[RequiredDate]]) -> 44960 | O4: Europe | P4: United Kingdom | Q4: London | R4: Enterprise | S4: Distributor | T4: G. Dubois | U4: Accessories | V4: ACC-3645 | W4: 873.06 | X4: =Table1[[#This Row],[UnitCost]]*(1+'scenario modeling'!$B$3) -> 960.366 | Y4: 2101.55 | Z4: =IF(Table1[[#This Row],[UnitPrice]]<=Quantiles!$B$2,Quantiles!$A$2,IF(Table1[[#This Row],[UnitPrice]]<=Quantiles!$B$3,Quantiles!$A$3,Quantiles!$A$4)) -> High | AA4: 0.066 | AB4: =MIN(Table1[[#This Row],[DiscountPct]],'scenario modeling'!$B$2) -> 0.066 | AC4: =IF(Table1[[#This Row],[DiscountPct]]>0.3, ">0.3","") | AD4: 10 | AE4: =Table1[[#This Row],[Quantity]]*(1+'scenario modeling'!$B$4) -> 12 | AF4: =Table1[[#This Row],[UnitCost]]*Table1[[#This Row],[Quantity]] -> 8730.6 | AG4: =SUMIF($U:U,Table1[[#This Row],[ProductCategory]],$AM:AM) -> 1331102.9 | AH4: =SUMIFS($AM$2:AM4,$U$2:U4,U4) -> 51124.985 | AI4: =Table1[[#This Row],[Cumulative_revenue]]/Table1[[#This Row],[Category_revenue]] -> 0.038407987 | AJ4: =IF(Table1[[#This Row],[cumulative_pct]]<=0.8,"A",IF(Table1[[#This Row],[cumulative_pct]]<=0.95,"B","C")) -> A | AK4: =Table1[[#This Row],[adj_unit_cost]]*Table1[[#This Row],[scenario_quantity]] -> 11524.392 | AL4: =Table1[[#This Row],[UnitPrice]]*Table1[[#This Row],[scenario_quantity]]*(1-Table1[[#This Row],[cap_adjusted_discount]]) -> 23554.172 | AM4: =Table1[[#This Row],[UnitPrice]]*Table1[[#This Row],[Quantity]]*(1-Table1[[#This Row],[DiscountPct]]) -> 19628.477 | AN4: =Table1[[#This Row],[gross_revenue]]-Table1[[#This Row],[cost_of_goods]] -> 10897.877 | AO4: =Table1[[#This Row],[scenario_revenue]]-Table1[[#This Row],[Scenario_unit_cost]] -> 12029.78 | AP4: =IF(Table1[[#This Row],[gross_revenue]]=0,0,Table1[[#This Row],[gross_profit]]/Table1[[#This Row],[gross_revenue]]) -> 0.55520747
A5: ORD-2023-107265 | B5: =_xlfn.TEXTAFTER(Table1[[#This Row],[OrderID]],"-",2) -> 107265 | C5: =YEAR(Table1[[#This Row],[OrderDate]]) -> 2023 | D5: =_xlfn.MINIFS(F:F,P:P,Table1[[#This Row],[Country]]) -> 44988 | E5: =DATEDIF(Table1[[#This Row],[first_time_orders]],Table1[[#This Row],[OrderDate]],"m") -> 1 | F5: 45038 | G5: =TEXT(Table1[[#This Row],[OrderDate]],"MMM-YYYY") -> Apr-2023 | H5: =MONTH(Table1[[#This Row],[OrderDate]]) -> 4 | I5: ="Q"&ROUNDUP(Table1[[#This Row],[months]]/3,0)&"-"&Table1[[#This Row],[order_year]] -> Q2-2023 | J5: =Table1[[#This Row],[RequiredDate]]-Table1[[#This Row],[OrderDate]] -> 22 | K5: =IF(Table1[[#This Row],[lead_time]]<0,MEDIAN(J:J),Table1[[#This Row],[lead_time]]) -> 22 | L5: =IF(Table1[[#This Row],[adj_lead_time]]<=7,1,0) -> 0 | M5: 45060 | N5: =IF(Table1[[#This Row],[lead_time]]<0,(Table1[[#This Row],[OrderDate]]+Table1[[#This Row],[adj_lead_time]]),Table1[[#This Row],[RequiredDate]]) -> 45060 | O5: Asia | P5: Japan | Q5: Nagoya | R5: Enterprise | S5: Retail | T5: A. Patel | U5: Accessories | V5: ACC-7713 | W5: 1209.22 | X5: =Table1[[#This Row],[UnitCost]]*(1+'scenario modeling'!$B$3) -> 1330.142 | Y5: 1404.33 | Z5: =IF(Table1[[#This Row],[UnitPrice]]<=Quantiles!$B$2,Quantiles!$A$2,IF(Table1[[#This Row],[UnitPrice]]<=Quantiles!$B$3,Quantiles!$A$3,Quantiles!$A$4)) -> Medium | AA5: 0.103 | AB5: =MIN(Table1[[#This Row],[DiscountPct]],'scenario modeling'!$B$2) -> 0.1 | AC5: =IF(Table1[[#This Row],[DiscountPct]]>0.3, ">0.3","") | AD5: 11 | AE5: =Table1[[#This Row],[Quantity]]*(1+'scenario modeling'!$B$4) -> 13.2 | AF5: =Table1[[#This Row],[UnitCost]]*Table1[[#This Row],[Quantity]] -> 13301.42 | AG5: =SUMIF($U:U,Table1[[#This Row],[ProductCategory]],$AM:AM) -> 1331102.9 | AH5: =SUMIFS($AM$2:AM5,$U$2:U5,U5) -> 64981.509 | AI5: =Table1[[#This Row],[Cumulative_revenue]]/Table1[[#This Row],[Category_revenue]] -> 0.048817794 | AJ5: =IF(Table1[[#This Row],[cumulative_pct]]<=0.8,"A",IF(Table1[[#This Row],[cumulative_pct]]<=0.95,"B","C")) -> A | AK5: =Table1[[#This Row],[adj_unit_cost]]*Table1[[#This Row],[scenario_quantity]] -> 17557.874 | AL5: =Table1[[#This Row],[UnitPrice]]*Table1[[#This Row],[scenario_quantity]]*(1-Table1[[#This Row],[cap_adjusted_discount]]) -> 16683.44 | AM5: =Table1[[#This Row],[UnitPrice]]*Table1[[#This Row],[Quantity]]*(1-Table1[[#This Row],[DiscountPct]]) -> 13856.524 | AN5: =Table1[[#This Row],[gross_revenue]]-Table1[[#This Row],[cost_of_goods]] -> 555.10411 | AO5: =Table1[[#This Row],[scenario_revenue]]-Table1[[#This Row],[Scenario_unit_cost]] -> -874.434 | AP5: =IF(Table1[[#This Row],[gross_revenue]]=0,0,Table1[[#This Row],[gross_profit]]/Table1[[#This Row],[gross_revenue]]) -> 0.040060848
A6: ORD-2023-674887 | B6: =_xlfn.TEXTAFTER(Table1[[#This Row],[OrderID]],"-",2) -> 674887 | C6: =YEAR(Table1[[#This Row],[OrderDate]]) -> 2023 | D6: =_xlfn.MINIFS(F:F,P:P,Table1[[#This Row],[Country]]) -> 44938 | E6: =DATEDIF(Table1[[#This Row],[first_time_orders]],Table1[[#This Row],[OrderDate]],"m") -> 11 | F6: 45276 | G6: =TEXT(Table1[[#This Row],[OrderDate]],"MMM-YYYY") -> Dec-2023 | H6: =MONTH(Table1[[#This Row],[OrderDate]]) -> 12 | I6: ="Q"&ROUNDUP(Table1[[#This Row],[months]]/3,0)&"-"&Table1[[#This Row],[order_year]] -> Q4-2023 | J6: =Table1[[#This Row],[RequiredDate]]-Table1[[#This Row],[OrderDate]] -> 3 | K6: =IF(Table1[[#This Row],[lead_time]]<0,MEDIAN(J:J),Table1[[#This Row],[lead_time]]) -> 3 | L6: =IF(Table1[[#This Row],[adj_lead_time]]<=7,1,0) -> 1 | M6: 45279 | N6: =IF(Table1[[#This Row],[lead_time]]<0,(Table1[[#This Row],[OrderDate]]+Table1[[#This Row],[adj_lead_time]]),Table1[[#This Row],[RequiredDate]]) -> 45279 | O6: Asia | P6: China | Q6: Beijing | R6: Education | S6: Retail | T6: A. Patel | U6: Accessories | V6: ACC-9644 | W6: 1415.05 | X6: =Table1[[#This Row],[UnitCost]]*(1+'scenario modeling'!$B$3) -> 1556.555 | Y6: 1972.38 | Z6: =IF(Table1[[#This Row],[UnitPrice]]<=Quantiles!$B$2,Quantiles!$A$2,IF(Table1[[#This Row],[UnitPrice]]<=Quantiles!$B$3,Quantiles!$A$3,Quantiles!$A$4)) -> High | AA6: 0 | AB6: =MIN(Table1[[#This Row],[DiscountPct]],'scenario modeling'!$B$2) -> 0 | AC6: =IF(Table1[[#This Row],[DiscountPct]]>0.3, ">0.3","") | AD6: 12 | AE6: =Table1[[#This Row],[Quantity]]*(1+'scenario modeling'!$B$4) -> 14.4 | AF6: =Table1[[#This Row],[UnitCost]]*Table1[[#This Row],[Quantity]] -> 16980.6 | AG6: =SUMIF($U:U,Table1[[#This Row],[ProductCategory]],$AM:AM) -> 1331102.9 | AH6: =SUMIFS($AM$2:AM6,$U$2:U6,U6) -> 88650.069 | AI6: =Table1[[#This Row],[Cumulative_revenue]]/Table1[[#This Row],[Category_revenue]] -> 0.066598958 | AJ6: =IF(Table1[[#This Row],[cumulative_pct]]<=0.8,"A",IF(Table1[[#This Row],[cumulative_pct]]<=0.95,"B","C")) -> A | AK6: =Table1[[#This Row],[adj_unit_cost]]*Table1[[#This Row],[scenario_quantity]] -> 22414.392 | AL6: =Table1[[#This Row],[UnitPrice]]*Table1[[#This Row],[scenario_quantity]]*(1-Table1[[#This Row],[cap_adjusted_discount]]) -> 28402.272 | AM6: =Table1[[#This Row],[UnitPrice]]*Table1[[#This Row],[Quantity]]*(1-Table1[[#This Row],[DiscountPct]]) -> 23668.56 | AN6: =Table1[[#This Row],[gross_revenue]]-Table1[[#This Row],[cost_of_goods]] -> 6687.96 | AO6: =Table1[[#This Row],[scenario_revenue]]-Table1[[#This Row],[Scenario_unit_cost]] -> 5987.88 | AP6: =IF(Table1[[#This Row],[gross_revenue]]=0,0,Table1[[#This Row],[gross_profit]]/Table1[[#This Row],[gross_revenue]]) -> 0.28256725
A7: ORD-2023-808024 | B7: =_xlfn.TEXTAFTER(Table1[[#This Row],[OrderID]],"-",2) -> 808024 | C7: =YEAR(Table1[[#This Row],[OrderDate]]) -> 2023 | D7: =_xlfn.MINIFS(F:F,P:P,Table1[[#This Row],[Country]]) -> 44936 | E7: =DATEDIF(Table1[[#This Row],[first_time_orders]],Table1[[#This Row],[OrderDate]],"m") -> 11 | F7: 45290 | G7: =TEXT(Table1[[#This Row],[OrderDate]],"MMM-YYYY") -> Dec-2023 | H7: =MONTH(Table1[[#This Row],[OrderDate]]) -> 12 | I7: ="Q"&ROUNDUP(Table1[[#This Row],[months]]/3,0)&"-"&Table1[[#This Row],[order_year]] -> Q4-2023 | J7: =Table1[[#This Row],[RequiredDate]]-Table1[[#This Row],[OrderDate]] -> 9 | K7: =IF(Table1[[#This Row],[lead_time]]<0,MEDIAN(J:J),Table1[[#This Row],[lead_time]]) -> 9 | L7: =IF(Table1[[#This Row],[adj_lead_time]]<=7,1,0) -> 0 | M7: 45299 | N7: =IF(Table1[[#This Row],[lead_time]]<0,(Table1[[#This Row],[OrderDate]]+Table1[[#This Row],[adj_lead_time]]),Table1[[#This Row],[RequiredDate]]) -> 45299 | O7: Europe | P7: France | Q7: Marseille | R7: Consumer | S7: Marketplace | T7: L. Okafor | U7: Accessories | V7: ACC-6594 | W7: 861.1 | X7: =Table1[[#This Row],[UnitCost]]*(1+'scenario modeling'!$B$3) -> 947.21 | Y7: 1224.72 | Z7: =IF(Table1[[#This Row],[UnitPrice]]<=Quantiles!$B$2,Quantiles!$A$2,IF(Table1[[#This Row],[UnitPrice]]<=Quantiles!$B$3,Quantiles!$A$3,Quantiles!$A$4)) -> Medium | AA7: 0.174 | AB7: =MIN(Table1[[#This Row],[DiscountPct]],'scenario modeling'!$B$2) -> 0.1 | AC7: =IF(Table1[[#This Row],[DiscountPct]]>0.3, ">0.3","") | AD7: 24 | AE7: =Table1[[#This Row],[Quantity]]*(1+'scenario modeling'!$B$4) -> 28.8 | AF7: =Table1[[#This Row],[UnitCost]]*Table1[[#This Row],[Quantity]] -> 20666.4 | AG7: =SUMIF($U:U,Table1[[#This Row],[ProductCategory]],$AM:AM) -> 1331102.9 | AH7: =SUMIFS($AM$2:AM7,$U$2:U7,U7) -> 112928.92 | AI7: =Table1[[#This Row],[Cumulative_revenue]]/Table1[[#This Row],[Category_revenue]] -> 0.084838606 | AJ7: =IF(Table1[[#This Row],[cumulative_pct]]<=0.8,"A",IF(Table1[[#This Row],[cumulative_pct]]<=0.95,"B","C")) -> A | AK7: =Table1[[#This Row],[adj_unit_cost]]*Table1[[#This Row],[scenario_quantity]] -> 27279.648 | AL7: =Table1[[#This Row],[UnitPrice]]*Table1[[#This Row],[scenario_quantity]]*(1-Table1[[#This Row],[cap_adjusted_discount]]) -> 31744.742 | AM7: =Table1[[#This Row],[UnitPrice]]*Table1[[#This Row],[Quantity]]*(1-Table1[[#This Row],[DiscountPct]]) -> 24278.849 | AN7: =Table1[[#This Row],[gross_revenue]]-Table1[[#This Row],[cost_of_goods]] -> 3612.4493 | AO7: =Table1[[#This Row],[scenario_revenue]]-Table1[[#This Row],[Scenario_unit_cost]] -> 4465.0944 | AP7: =IF(Table1[[#This Row],[gross_revenue]]=0,0,Table1[[#This Row],[gross_profit]]/Table1[[#This Row],[gross_revenue]]) -> 0.14878997
A8: ORD-2024-921935 | B8: =_xlfn.TEXTAFTER(Table1[[#This Row],[OrderID]],"-",2) -> 921935 | C8: =YEAR(Table1[[#This Row],[OrderDate]]) -> 2024 | D8: =_xlfn.MINIFS(F:F,P:P,Table1[[#This Row],[Country]]) -> 44945 | E8: =DATEDIF(Table1[[#This Row],[first_time_orders]],Table1[[#This Row],[OrderDate]],"m") -> 11 | F8: 45292 | G8: =TEXT(Table1[[#This Row],[OrderDate]],"MMM-YYYY") -> Jan-2024 | H8: =MONTH(Table1[[#This Row],[OrderDate]]) -> 1 | I8: ="Q"&ROUNDUP(Table1[[#This Row],[months]]/3,0)&"-"&Table1[[#This Row],[order_year]] -> Q1-2024 | J8: =Table1[[#This Row],[RequiredDate]]-Table1[[#This Row],[OrderDate]] -> 26 | K8: =IF(Table1[[#This Row],[lead_time]]<0,MEDIAN(J:J),Table1[[#This Row],[lead_time]]) -> 26 | L8: =IF(Table1[[#This Row],[adj_lead_time]]<=7,1,0) -> 0 | M8: 45318 | N8: =IF(Table1[[#This Row],[lead_time]]<0,(Table1[[#This Row],[OrderDate]]+Table1[[#This Row],[adj_lead_time]]),Table1[[#This Row],[RequiredDate]]) -> 45318 | O8: Europe | P8: United Kingdom | Q8: Manchester | R8: Education | S8: Distributor | T8: D. Smith | U8: Accessories | V8: ACC-3103 | W8: 657.45 | X8: =Table1[[#This Row],[UnitCost]]*(1+'scenario modeling'!$B$3) -> 723.195 | Y8: 1325.96 | Z8: =IF(Table1[[#This Row],[UnitPrice]]<=Quantiles!$B$2,Quantiles!$A$2,IF(Table1[[#This Row],[UnitPrice]]<=Quantiles!$B$3,Quantiles!$A$3,Quantiles!$A$4)) -> Medium | AA8: 0.167 | AB8: =MIN(Table1[[#This Row],[DiscountPct]],'scenario modeling'!$B$2) -> 0.1 | AC8: =IF(Table1[[#This Row],[DiscountPct]]>0.3, ">0.3","") | AD8: 21 | AE8: =Table1[[#This Row],[Quantity]]*(1+'scenario modeling'!$B$4) -> 25.2 | AF8: =Table1[[#This Row],[UnitCost]]*Table1[[#This Row],[Quantity]] -> 13806.45 | AG8: =SUMIF($U:U,Table1[[#This Row],[ProductCategory]],$AM:AM) -> 1331102.9 | AH8: =SUMIFS($AM$2:AM8,$U$2:U8,U8) -> 136123.94 | AI8: =Table1[[#This Row],[Cumulative_revenue]]/Table1[[#This Row],[Category_revenue]] -> 0.10226402 | AJ8: =IF(Table1[[#This Row],[cumulative_pct]]<=0.8,"A",IF(Table1[[#This Row],[cumulative_pct]]<=0.95,"B","C")) -> A | AK8: =Table1[[#This Row],[adj_unit_cost]]*Table1[[#This Row],[scenario_quantity]] -> 18224.514 | AL8: =Table1[[#This Row],[UnitPrice]]*Table1[[#This Row],[scenario_quantity]]*(1-Table1[[#This Row],[cap_adjusted_discount]]) -> 30072.773 | AM8: =Table1[[#This Row],[UnitPrice]]*Table1[[#This Row],[Quantity]]*(1-Table1[[#This Row],[DiscountPct]]) -> 23195.018 | AN8: =Table1[[#This Row],[gross_revenue]]-Table1[[#This Row],[cost_of_goods]] -> 9388.5683 | AO8: =Table1[[#This Row],[scenario_revenue]]-Table1[[#This Row],[Scenario_unit_cost]] -> 11848.259 | AP8: =IF(Table1[[#This Row],[gross_revenue]]=0,0,Table1[[#This Row],[gross_profit]]/Table1[[#This Row],[gross_revenue]]) -> 0.40476658
A9: ORD-2024-277241 | B9: =_xlfn.TEXTAFTER(Table1[[#This Row],[OrderID]],"-",2) -> 277241 | C9: =YEAR(Table1[[#This Row],[OrderDate]]) -> 2024 | D9: =_xlfn.MINIFS(F:F,P:P,Table1[[#This Row],[Country]]) -> 44933 | E9: =DATEDIF(Table1[[#This Row],[first_time_orders]],Table1[[#This Row],[OrderDate]],"m") -> 12 | F9: 45319 | G9: =TEXT(Table1[[#This Row],[OrderDate]],"MMM-YYYY") -> Jan-2024 | H9: =MONTH(Table1[[#This Row],[OrderDate]]) -> 1 | I9: ="Q"&ROUNDUP(Table1[[#This Row],[months]]/3,0)&"-"&Table1[[#This Row],[order_year]] -> Q1-2024 | J9: =Table1[[#This Row],[RequiredDate]]-Table1[[#This Row],[OrderDate]] -> 2 | K9: =IF(Table1[[#This Row],[lead_time]]<0,MEDIAN(J:J),Table1[[#This Row],[lead_time]]) -> 2 | L9: =IF(Table1[[#This Row],[adj_lead_time]]<=7,1,0) -> 1 | M9: 45321 | N9: =IF(Table1[[#This Row],[lead_time]]<0,(Table1[[#This Row],[OrderDate]]+Table1[[#This Row],[adj_lead_time]]),Table1[[#This Row],[RequiredDate]]) -> 45321 | O9: Africa | P9: South Africa | Q9: Cape Town | R9: Consumer | S9: Direct | T9: F. Müller | U9: Accessories | V9: ACC-6223 | W9: 798.45 | X9: =Table1[[#This Row],[UnitCost]]*(1+'scenario modeling'!$B$3) -> 878.295 | Y9: 1592.02 | Z9: =IF(Table1[[#This Row],[UnitPrice]]<=Quantiles!$B$2,Quantiles!$A$2,IF(Table1[[#This Row],[UnitPrice]]<=Quantiles!$B$3,Quantiles!$A$3,Quantiles!$A$4)) -> Medium | AA9: 0.066 | AB9: =MIN(Table1[[#This Row],[DiscountPct]],'scenario modeling'!$B$2) -> 0.066 | AC9: =IF(Table1[[#This Row],[DiscountPct]]>0.3, ">0.3","") | AD9: 18 | AE9: =Table1[[#This Row],[Quantity]]*(1+'scenario modeling'!$B$4) -> 21.6 | AF9: =Table1[[#This Row],[UnitCost]]*Table1[[#This Row],[Quantity]] -> 14372.1 | AG9: =SUMIF($U:U,Table1[[#This Row],[ProductCategory]],$AM:AM) -> 1331102.9 | AH9: =SUMIFS($AM$2:AM9,$U$2:U9,U9) -> 162888.98 | AI9: =Table1[[#This Row],[Cumulative_revenue]]/Table1[[#This Row],[Category_revenue]] -> 0.12237143 | AJ9: =IF(Table1[[#This Row],[cumulative_pct]]<=0.8,"A",IF(Table1[[#This Row],[cumulative_pct]]<=0.95,"B","C")) -> A | AK9: =Table1[[#This Row],[adj_unit_cost]]*Table1[[#This Row],[scenario_quantity]] -> 18971.172 | AL9: =Table1[[#This Row],[UnitPrice]]*Table1[[#This Row],[scenario_quantity]]*(1-Table1[[#This Row],[cap_adjusted_discount]]) -> 32118.048 | AM9: =Table1[[#This Row],[UnitPrice]]*Table1[[#This Row],[Quantity]]*(1-Table1[[#This Row],[DiscountPct]]) -> 26765.04 | AN9: =Table1[[#This Row],[gross_revenue]]-Table1[[#This Row],[cost_of_goods]] -> 12392.94 | AO9: =Table1[[#This Row],[scenario_revenue]]-Table1[[#This Row],[Scenario_unit_cost]] -> 13146.876 | AP9: =IF(Table1[[#This Row],[gross_revenue]]=0,0,Table1[[#This Row],[gross_profit]]/Table1[[#This Row],[gross_revenue]]) -> 0.46302715
A10: ORD-2024-210687 | B10: =_xlfn.TEXTAFTER(Table1[[#This Row],[OrderID]],"-",2) -> 210687 | C10: =YEAR(Table1[[#This Row],[OrderDate]]) -> 2024 | D10: =_xlfn.MINIFS(F:F,P:P,Table1[[#This Row],[Country]]) -> 44948 | E10: =DATEDIF(Table1[[#This Row],[first_time_orders]],Table1[[#This Row],[OrderDate]],"m") -> 12 | F10: 45319 | G10: =TEXT(Table1[[#This Row],[OrderDate]],"MMM-YYYY") -> Jan-2024 | H10: =MONTH(Table1[[#This Row],[OrderDate]]) -> 1 | I10: ="Q"&ROUNDUP(Table1[[#This Row],[months]]/3,0)&"-"&Table1[[#This Row],[order_year]] -> Q1-2024 | J10: =Table1[[#This Row],[RequiredDate]]-Table1[[#This Row],[OrderDate]] -> 12 | K10: =IF(Table1[[#This Row],[lead_time]]<0,MEDIAN(J:J),Table1[[#This Row],[lead_time]]) -> 12 | L10: =IF(Table1[[#This Row],[adj_lead_time]]<=7,1,0) -> 0 | M10: 45331 | N10: =IF(Table1[[#This Row],[lead_time]]<0,(Table1[[#This Row],[OrderDate]]+Table1[[#This Row],[adj_lead_time]]),Table1[[#This Row],[RequiredDate]]) -> 45331 | O10: Europe | P10: Germany | Q10: Berlin | R10: Corporate | S10: Online | T10: G. Dubois | U10: Accessories | V10: ACC-7938 | W10: 644.17 | X10: =Table1[[#This Row],[UnitCost]]*(1+'scenario modeling'!$B$3) -> 708.587 | Y10: 700.12 | Z10: =IF(Table1[[#This Row],[UnitPrice]]<=Quantiles!$B$2,Quantiles!$A$2,IF(Table1[[#This Row],[UnitPrice]]<=Quantiles!$B$3,Quantiles!$A$3,Quantiles!$A$4)) -> Low | AA10: 0.006 | AB10: =MIN(Table1[[#This Row],[DiscountPct]],'scenario modeling'!$B$2) -> 0.006 | AC10: =IF(Table1[[#This Row],[DiscountPct]]>0.3, ">0.3","") | AD10: 23 | AE10: =Table1[[#This Row],[Quantity]]*(1+'scenario modeling'!$B$4) -> 27.6 | AF10: =Table1[[#This Row],[UnitCost]]*Table1[[#This Row],[Quantity]] -> 14815.91 | AG10: =SUMIF($U:U,Table1[[#This Row],[ProductCategory]],$AM:AM) -> 1331102.9 | AH10: =SUMIFS($AM$2:AM10,$U$2:U10,U10) -> 178895.12 | AI10: =Table1[[#This Row],[Cumulative_revenue]]/Table1[[#This Row],[Category_revenue]] -> 0.13439616 | AJ10: =IF(Table1[[#This Row],[cumulative_pct]]<=0.8,"A",IF(Table1[[#This Row],[cumulative_pct]]<=0.95,"B","C")) -> A | AK10: =Table1[[#This Row],[adj_unit_cost]]*Table1[[#This Row],[scenario_quantity]] -> 19557.001 | AL10: =Table1[[#This Row],[UnitPrice]]*Table1[[#This Row],[scenario_quantity]]*(1-Table1[[#This Row],[cap_adjusted_discount]]) -> 19207.372 | AM10: =Table1[[#This Row],[UnitPrice]]*Table1[[#This Row],[Quantity]]*(1-Table1[[#This Row],[DiscountPct]]) -> 16006.143 | AN10: =Table1[[#This Row],[gross_revenue]]-Table1[[#This Row],[cost_of_goods]] -> 1190.2334 | AO10: =Table1[[#This Row],[scenario_revenue]]-Table1[[#This Row],[Scenario_unit_cost]] -> -349.62907 | AP10: =IF(Table1[[#This Row],[gross_revenue]]=0,0,Table1[[#This Row],[gross_profit]]/Table1[[#This Row],[gross_revenue]]) -> 0.074361038
A11: ORD-2024-232632 | B11: =_xlfn.TEXTAFTER(Table1[[#This Row],[OrderID]],"-",2) -> 232632 | C11: =YEAR(Table1[[#This Row],[OrderDate]]) -> 2024 | D11: =_xlfn.MINIFS(F:F,P:P,Table1[[#This Row],[Country]]) -> 44938 | E11: =DATEDIF(Table1[[#This Row],[first_time_orders]],Table1[[#This Row],[OrderDate]],"m") -> 13 | F11: 45336 | G11: =TEXT(Table1[[#This Row],[OrderDate]],"MMM-YYYY") -> Feb-2024 | H11: =MONTH(Table1[[#This Row],[OrderDate]]) -> 2 | I11: ="Q"&ROUNDUP(Table1[[#This Row],[months]]/3,0)&"-"&Table1[[#This Row],[order_year]] -> Q1-2024 | J11: =Table1[[#This Row],[RequiredDate]]-Table1[[#This Row],[OrderDate]] -> 0 | K11: =IF(Table1[[#This Row],[lead_time]]<0,MEDIAN(J:J),Table1[[#This Row],[lead_time]]) -> 0 | L11: =IF(Table1[[#This Row],[adj_lead_time]]<=7,1,0) -> 1 | M11: 45336 | N11: =IF(Table1[[#This Row],[lead_time]]<0,(Table1[[#This Row],[OrderDate]]+Table1[[#This Row],[adj_lead_time]]),Table1[[#This Row],[RequiredDate]]) -> 45336 | O11: Asia | P11: China | Q11: Beijing | R11: Corporate | S11: Distributor | T11: L. Okafor | U11: Accessories | V11: ACC-1021 | W11: 65.93 | X11: =Table1[[#This Row],[UnitCost]]*(1+'scenario modeling'!$B$3) -> 72.523 | Y11: 84.9 | Z11: =IF(Table1[[#This Row],[UnitPrice]]<=Quantiles!$B$2,Quantiles!$A$2,IF(Table1[[#This Row],[UnitPrice]]<=Quantiles!$B$3,Quantiles!$A$3,Quantiles!$A$4)) -> Low | AA11: 0.259 | AB11: =MIN(Table1[[#This Row],[DiscountPct]],'scenario modeling'!$B$2) -> 0.1 | AC11: =IF(Table1[[#This Row],[DiscountPct]]>0.3, ">0.3","") | AD11: 23 | AE11: =Table1[[#This Row],[Quantity]]*(1+'scenario modeling'!$B$4) -> 27.6 | AF11: =Table1[[#This Row],[UnitCost]]*Table1[[#This Row],[Quantity]] -> 1516.39 | AG11: =SUMIF($U:U,Table1[[#This Row],[ProductCategory]],$AM:AM) -> 1331102.9 | AH11: =SUMIFS($AM$2:AM11,$U$2:U11,U11) -> 180342.07 | AI11: =Table1[[#This Row],[Cumulative_revenue]]/Table1[[#This Row],[Category_revenue]] -> 0.13548319 | AJ11: =IF(Table1[[#This Row],[cumulative_pct]]<=0.8,"A",IF(Table1[[#This Row],[cumulative_pct]]<=0.95,"B","C")) -> A | AK11: =Table1[[#This Row],[adj_unit_cost]]*Table1[[#This Row],[scenario_quantity]] -> 2001.6348 | AL11: =Table1[[#This Row],[UnitPrice]]*Table1[[#This Row],[scenario_quantity]]*(1-Table1[[#This Row],[cap_adjusted_discount]]) -> 2108.916 | AM11: =Table1[[#This Row],[UnitPrice]]*Table1[[#This Row],[Quantity]]*(1-Table1[[#This Row],[DiscountPct]]) -> 1446.9507 | AN11: =Table1[[#This Row],[gross_revenue]]-Table1[[#This Row],[cost_of_goods]] -> -69.4393 | AO11: =Table1[[#This Row],[scenario_revenue]]-Table1[[#This Row],[Scenario_unit_cost]] -> 107.2812 | AP11: =IF(Table1[[#This Row],[gross_revenue]]=0,0,Table1[[#This Row],[gross_profit]]/Table1[[#This Row],[gross_revenue]]) -> -0.047990094
A12: ORD-2024-287210 | B12: =_xlfn.TEXTAFTER(Table1[[#This Row],[OrderID]],"-",2) -> 287210 | C12: =YEAR(Table1[[#This Row],[OrderDate]]) -> 2024 | D12: =_xlfn.MINIFS(F:F,P:P,Table1[[#This Row],[Country]]) -> 44948 | E12: =DATEDIF(Table1[[#This Row],[first_time_orders]],Table1[[#This Row],[OrderDate]],"m") -> 13 | F12: 45369 | G12: =TEXT(Table1[[#This Row],[OrderDate]],"MMM-YYYY") -> Mar-2024 | H12: =MONTH(Table1[[#This Row],[OrderDate]]) -> 3 | I12: ="Q"&ROUNDUP(Table1[[#This Row],[months]]/3,0)&"-"&Table1[[#This Row],[order_year]] -> Q1-2024 | J12: =Table1[[#This Row],[RequiredDate]]-Table1[[#This Row],[OrderDate]] -> 3 | K12: =IF(Table1[[#This Row],[lead_time]]<0,MEDIAN(J:J),Table1[[#This Row],[lead_time]]) -> 3 | L12: =IF(Table1[[#This Row],[adj_lead_time]]<=7,1,0) -> 1 | M12: 45372 | N12: =IF(Table1[[#This Row],[lead_time]]<0,(Table1[[#This Row],[OrderDate]]+Table1[[#This Row],[adj_lead_time]]),Table1[[#This Row],[RequiredDate]]) -> 45372 | O12: Europe | P12: Germany | Q12: Munich | R12: Small Business | S12: Online | T12: M. Rossi | U12: Accessories | V12: ACC-2761 | W12: 910.63 | X12: =Table1[[#This Row],[UnitCost]]*(1+'scenario modeling'!$B$3) -> 1001.693 | Y12: 1269.4 | Z12: =IF(Table1[[#This Row],[UnitPrice]]<=Quantiles!$B$2,Quantiles!$A$2,IF(Table1[[#This Row],[UnitPrice]]<=Quantiles!$B$3,Quantiles!$A$3,Quantiles!$A$4)) -> Medium | AA12: 0.068 | AB12: =MIN(Table1[[#This Row],[DiscountPct]],'scenario modeling'!$B$2) -> 0.068 | AC12: =IF(Table1[[#This Row],[DiscountPct]]>0.3, ">0.3","") | AD12: 9 | AE12: =Table1[[#This Row],[Quantity]]*(1+'scenario modeling'!$B$4) -> 10.8 | AF12: =Table1[[#This Row],[UnitCost]]*Table1[[#This Row],[Quantity]] -> 8195.67 | AG12: =SUMIF($U:U,Table1[[#This Row],[ProductCategory]],$AM:AM) -> 1331102.9 | AH12: =SUMIFS($AM$2:AM12,$U$2:U12,U12) -> 190989.8 | AI12: =Table1[[#This Row],[Cumulative_revenue]]/Table1[[#This Row],[Category_revenue]] -> 0.14348236 | AJ12: =IF(Table1[[#This Row],[cumulative_pct]]<=0.8,"A",IF(Table1[[#This Row],[cumulative_pct]]<=0.95,"B","C")) -> A | AK12: =Table1[[#This Row],[adj_unit_cost]]*Table1[[#This Row],[scenario_quantity]] -> 10818.284 | AL12: =Table1[[#This Row],[UnitPrice]]*Table1[[#This Row],[scenario_quantity]]*(1-Table1[[#This Row],[cap_adjusted_discount]]) -> 12777.273 | AM12: =Table1[[#This Row],[UnitPrice]]*Table1[[#This Row],[Quantity]]*(1-Table1[[#This Row],[DiscountPct]]) -> 10647.727 | AN12: =Table1[[#This Row],[gross_revenue]]-Table1[[#This Row],[cost_of_goods]] -> 2452.0572 | AO12: =Table1[[#This Row],[scenario_revenue]]-Table1[[#This Row],[Scenario_unit_cost]] -> 1958.9882 | AP12: =IF(Table1[[#This Row],[gross_revenue]]=0,0,Table1[[#This Row],[gross_profit]]/Table1[[#This Row],[gross_revenue]]) -> 0.23028926
A13: ORD-2024-211453 | B13: =_xlfn.TEXTAFTER(Table1[[#This Row],[OrderID]],"-",2) -> 211453 | C13: =YEAR(Table1[[#This Row],[OrderDate]]) -> 2024 | D13: =_xlfn.MINIFS(F:F,P:P,Table1[[#This Row],[Country]]) -> 44948 | E13: =DATEDIF(Table1[[#This Row],[first_time_orders]],Table1[[#This Row],[OrderDate]],"m") -> 14 | F13: 45386 | G13: =TEXT(Table1[[#This Row],[OrderDate]],"MMM-YYYY") -> Apr-2024 | H13: =MONTH(Table1[[#This Row],[OrderDate]]) -> 4 | I13: ="Q"&ROUNDUP(Table1[[#This Row],[months]]/3,0)&"-"&Table1[[#This Row],[order_year]] -> Q2-2024 | J13: =Table1[[#This Row],[RequiredDate]]-Table1[[#This Row],[OrderDate]] -> 20 | K13: =IF(Table1[[#This Row],[lead_time]]<0,MEDIAN(J:J),Table1[[#This Row],[lead_time]]) -> 20 | L13: =IF(Table1[[#This Row],[adj_lead_time]]<=7,1,0) -> 0 | M13: 45406 | N13: =IF(Table1[[#This Row],[lead_time]]<0,(Table1[[#This Row],[OrderDate]]+Table1[[#This Row],[adj_lead_time]]),Table1[[#This Row],[RequiredDate]]) -> 45406 | O13: Europe | P13: Germany | Q13: Frankfurt | R13: Non-Profit | S13: Direct | T13: O. Wang | U13: Accessories | V13: ACC-6543 | W13: 683.42 | X13: =Table1[[#This Row],[UnitCost]]*(1+'scenario modeling'!$B$3) -> 751.762 | Y13: 951.51 | Z13: =IF(Table1[[#This Row],[UnitPrice]]<=Quantiles!$B$2,Quantiles!$A$2,IF(Table1[[#This Row],[UnitPrice]]<=Quantiles!$B$3,Quantiles!$A$3,Quantiles!$A$4)) -> Medium | AA13: 0 | AB13: =MIN(Table1[[#This Row],[DiscountPct]],'scenario modeling'!$B$2) -> 0 | AC13: =IF(Table1[[#This Row],[DiscountPct]]>0.3, ">0.3","") | AD13: 14 | AE13: =Table1[[#This Row],[Quantity]]*(1+'scenario modeling'!$B$4) -> 16.8 | AF13: =Table1[[#This Row],[UnitCost]]*Table1[[#This Row],[Quantity]] -> 9567.88 | AG13: =SUMIF($U:U,Table1[[#This Row],[ProductCategory]],$AM:AM) -> 1331102.9 | AH13: =SUMIFS($AM$2:AM13,$U$2:U13,U13) -> 204310.94 | AI13: =Table1[[#This Row],[Cumulative_revenue]]/Table1[[#This Row],[Category_revenue]] -> 0.15348996 | AJ13: =IF(Table1[[#This Row],[cumulative_pct]]<=0.8,"A",IF(Table1[[#This Row],[cumulative_pct]]<=0.95,"B","C")) -> A | AK13: =Table1[[#This Row],[adj_unit_cost]]*Table1[[#This Row],[scenario_quantity]] -> 12629.602 | AL13: =Table1[[#This Row],[UnitPrice]]*Table1[[#This Row],[scenario_quantity]]*(1-Table1[[#This Row],[cap_adjusted_discount]]) -> 15985.368 | AM13: =Table1[[#This Row],[UnitPrice]]*Table1[[#This Row],[Quantity]]*(1-Table1[[#This Row],[DiscountPct]]) -> 13321.14 | AN13: =Table1[[#This Row],[gross_revenue]]-Table1[[#This Row],[cost_of_goods]] -> 3753.26 | AO13: =Table1[[#This Row],[scenario_revenue]]-Table1[[#This Row],[Scenario_unit_cost]] -> 3355.7664 | AP13: =IF(Table1[[#This Row],[gross_revenue]]=0,0,Table1[[#This Row],[gross_profit]]/Table1[[#This Row],[gross_revenue]]) -> 0.28175216
... A633: ORD-2023-596758 | B633: =_xlfn.TEXTAFTER(Table1[[#This Row],[OrderID]],"-",2) -> 596758 | C633: =YEAR(Table1[[#This Row],[OrderDate]]) -> 2023 | D633: =_xlfn.MINIFS(F:F,P:P,Table1[[#This Row],[Country]]) -> 44988 | E633: =DATEDIF(Table1[[#This Row],[first_time_orders]],Table1[[#This Row],[OrderDate]],"m") -> 9 | F633: 45267 | G633: =TEXT(Table1[[#This Row],[OrderDate]],"MMM-YYYY") -> Dec-2023 | H633: =MONTH(Table1[[#This Row],[OrderDate]]) -> 12 | I633: ="Q"&ROUNDUP(Table1[[#This Row],[months]]/3,0)&"-"&Table1[[#This Row],[order_year]] -> Q4-2023 | J633: =Table1[[#This Row],[RequiredDate]]-Table1[[#This Row],[OrderDate]] -> -2 | K633: =IF(Table1[[#This Row],[lead_time]]<0,MEDIAN(J:J),Table1[[#This Row],[lead_time]]) -> 15 | L633: =IF(Table1[[#This Row],[adj_lead_time]]<=7,1,0) -> 0 | M633: 45265 | N633: =IF(Table1[[#This Row],[lead_time]]<0,(Table1[[#This Row],[OrderDate]]+Table1[[#This Row],[adj_lead_time]]),Table1[[#This Row],[RequiredDate]]) -> 45282 | O633: Asia | P633: Japan | Q633: Tokyo | R633: Non-Profit | S633: Marketplace | T633: H. Kim | U633: Printers | V633: PRN-8175 | W633: 1097.59 | X633: =Table1[[#This Row],[UnitCost]]*(1+'scenario modeling'!$B$3) -> 1207.349 | Y633: 845.55 | Z633: =IF(Table1[[#This Row],[UnitPrice]]<=Quantiles!$B$2,Quantiles!$A$2,IF(Table1[[#This Row],[UnitPrice]]<=Quantiles!$B$3,Quantiles!$A$3,Quantiles!$A$4)) -> Medium | AA633: 0.184 | AB633: =MIN(Table1[[#This Row],[DiscountPct]],'scenario modeling'!$B$2) -> 0.1 | AC633: =IF(Table1[[#This Row],[DiscountPct]]>0.3, ">0.3","") | AD633: 6 | AE633: =Table1[[#This Row],[Quantity]]*(1+'scenario modeling'!$B$4) -> 7.2 | AF633: =Table1[[#This Row],[UnitCost]]*Table1[[#This Row],[Quantity]] -> 6585.54 | AG633: =SUMIF($U:U,Table1[[#This Row],[ProductCategory]],$AM:AM) -> 1616102.7 | AH633: =SUMIFS($AM$2:AM633,$U$2:U633,U633) -> 1616102.7 | AI633: =Table1[[#This Row],[Cumulative_revenue]]/Table1[[#This Row],[Category_revenue]] -> 1 | AJ633: =IF(Table1[[#This Row],[cumulative_pct]]<=0.8,"A",IF(Table1[[#This Row],[cumulative_pct]]<=0.95,"B","C")) -> C | AK633: =Table1[[#This Row],[adj_unit_cost]]*Table1[[#This Row],[scenario_quantity]] -> 8692.9128 | AL633: =Table1[[#This Row],[UnitPrice]]*Table1[[#This Row],[scenario_quantity]]*(1-Table1[[#This Row],[cap_adjusted_discount]]) -> 5479.164 | AM633: =Table1[[#This Row],[UnitPrice]]*Table1[[#This Row],[Quantity]]*(1-Table1[[#This Row],[DiscountPct]]) -> 4139.8128 | AN633: =Table1[[#This Row],[gross_revenue]]-Table1[[#This Row],[cost_of_goods]] -> -2445.7272 | AO633: =Table1[[#This Row],[scenario_revenue]]-Table1[[#This Row],[Scenario_unit_cost]] -> -3213.7488 | AP633: =IF(Table1[[#This Row],[gross_revenue]]=0,0,Table1[[#This Row],[gross_profit]]/Table1[[#This Row],[gross_revenue]]) -> -0.59078208

Sheet scenario modeling
A1: Sceneraio Controls | B1: Values | F1: BASELINE REVENUE | G1: =SUM(clean_data!AM:AM) -> 10925968
A2: Global Discount Cap | B2: 0.1 | F2: BASELINE_PROFIT | G2: =SUM(clean_data!AN:AN) -> 3398219.9
A3: Unit Cost Inflation | B3: 0.1 | F3: MODELED_REVENUE | G3: =SUM(clean_data!AL:AL) -> 13790153
A4: Quantity Uplift | B4: 0.2 | F4: MODELED_PROFIT | G4: =SUM(clean_data!AO:AO) -> 3853525.8

Sheet lead_proxy
A1: {=_xlfn.UNIQUE(clean_data!P:P)} -> Country | B1: order count | C1: orders<=7days | D1: %<=7days
A2: Nigeria | B2: =COUNTIF(clean_data!P:P,lead_proxy!A2) -> 44 | C2: =SUMIF(clean_data!P:P,lead_proxy!A2,clean_data!L:L) -> 14 | D2: =C2/B2 -> 0.31818182
A3: India | B3: =COUNTIF(clean_data!P:P,lead_proxy!A3) -> 61 | C3: =SUMIF(clean_data!P:P,lead_proxy!A3,clean_data!L:L) -> 11 | D3: =C3/B3 -> 0.18032787
A4: United Kingdom | B4: =COUNTIF(clean_data!P:P,lead_proxy!A4) -> 54 | C4: =SUMIF(clean_data!P:P,lead_proxy!A4,clean_data!L:L) -> 13 | D4: =C4/B4 -> 0.24074074
A5: Japan | B5: =COUNTIF(clean_data!P:P,lead_proxy!A5) -> 59 | C5: =SUMIF(clean_data!P:P,lead_proxy!A5,clean_data!L:L) -> 10 | D5: =C5/B5 -> 0.16949153
A6: China | B6: =COUNTIF(clean_data!P:P,lead_proxy!A6) -> 51 | C6: =SUMIF(clean_data!P:P,lead_proxy!A6,clean_data!L:L) -> 9 | D6: =C6/B6 -> 0.17647059
A7: France | B7: =COUNTIF(clean_data!P:P,lead_proxy!A7) -> 54 | C7: =SUMIF(clean_data!P:P,lead_proxy!A7,clean_data!L:L) -> 12 | D7: =C7/B7 -> 0.22222222
A8: South Africa | B8: =COUNTIF(clean_data!P:P,lead_proxy!A8) -> 45 | C8: =SUMIF(clean_data!P:P,lead_proxy!A8,clean_data!L:L) -> 10 | D8: =C8/B8 -> 0.22222222
A9: Germany | B9: =COUNTIF(clean_data!P:P,lead_proxy!A9) -> 51 | C9: =SUMIF(clean_data!P:P,lead_proxy!A9,clean_data!L:L) -> 11 | D9: =C9/B9 -> 0.21568627
A10: Kenya | B10: =COUNTIF(clean_data!P:P,lead_proxy!A10) -> 56 | C10: =SUMIF(clean_data!P:P,lead_proxy!A10,clean_data!L:L) -> 15 | D10: =C10/B10 -> 0.26785714
A11: Brazil | B11: =COUNTIF(clean_data!P:P,lead_proxy!A11) -> 62 | C11: =SUMIF(clean_data!P:P,lead_proxy!A11,clean_data!L:L) -> 13 | D11: =C11/B11 -> 0.20967742
A12: Canada | B12: =COUNTIF(clean_data!P:P,lead_proxy!A12) -> 44 | C12: =SUMIF(clean_data!P:P,lead_proxy!A12,clean_data!L:L) -> 6 | D12: =C12/B12 -> 0.13636364
A13: USA | B13: =COUNTIF(clean_data!P:P,lead_proxy!A13) -> 51 | C13: =SUMIF(clean_data!P:P,lead_proxy!A13,clean_data!L:L) -> 14 | D13: =C13/B13 -> 0.2745098
A14: 0
A17: {=_xlfn.UNIQUE(clean_data!U:U)} -> ProductCategory | B17: order count | C17: orders<=7days | D17: %<=7days
A18: Accessories | B18: =COUNTIF(clean_data!U:U,lead_proxy!A18) -> 88 | C18: =SUMIF(Table1[ProductCategory],lead_proxy!A18,clean_data!L:L) -> 28 | D18: =C18/B18 -> 0.31818182
A19: Components | B19: =COUNTIF(clean_data!U:U,lead_proxy!A19) -> 91 | C19: =SUMIF(Table1[ProductCategory],lead_proxy!A19,clean_data!L:L) -> 19 | D19: =C19/B19 -> 0.20879121
A20: Laptops | B20: =COUNTIF(clean_data!U:U,lead_proxy!A20) -> 82 | C20: =SUMIF(Table1[ProductCategory],lead_proxy!A20,clean_data!L:L) -> 24 | D20: =C20/B20 -> 0.29268293
A21: Monitors | B21: =COUNTIF(clean_data!U:U,lead_proxy!A21) -> 94 | C21: =SUMIF(Table1[ProductCategory],lead_proxy!A21,clean_data!L:L) -> 14 | D21: =C21/B21 -> 0.14893617
A22: Networking | B22: =COUNTIF(clean_data!U:U,lead_proxy!A22) -> 86 | C22: =SUMIF(Table1[ProductCategory],lead_proxy!A22,clean_data!L:L) -> 18 | D22: =C22/B22 -> 0.20930233
A23: Phones | B23: =COUNTIF(clean_data!U:U,lead_proxy!A23) -> 88 | C23: =SUMIF(Table1[ProductCategory],lead_proxy!A23,clean_data!L:L) -> 15 | D23: =C23/B23 -> 0.17045455
A24: Printers | B24: =COUNTIF(clean_data!U:U,lead_proxy!A24) -> 103 | C24: =SUMIF(Table1[ProductCategory],lead_proxy!A24,clean_data!L:L) -> 20 | D24: =C24/B24 -> 0.19417476
A25: 0

Sheet sales
A1: {=_xlfn.UNIQUE(clean_data!T1:T633)} -> Salesperson | B1: Order_count | C1: First_order_date | D1: last_order_date | E1: operations_duration | F1: revenue | G1: profits | H1: average_discount | I1: Orders/month | J1: revenue/order | K1: profit/order
A2: D. Smith | B2: =COUNTIF(clean_data!T:T,sales!A2) -> 39 | C2: =_xlfn.MINIFS(clean_data!F:F,clean_data!T:T,sales!A2) -> 44936 | D2: =_xlfn.MAXIFS(clean_data!F:F,clean_data!T:T,sales!A2) -> 45914 | E2: =DATEDIF(C2,D2,"m") -> 32 | F2: =SUMIF(clean_data!T:T,sales!A2,clean_data!AM:AM) -> 614644.3 | G2: =SUMIF(clean_data!T:T,sales!A2,clean_data!AN:AN) -> 170472.52 | H2: =AVERAGEIF(Table1[Salesperson],sales!A2,clean_data!AA:AA) -> 0.11978947 | I2: =B2/E2 -> 1.21875 | J2: =F2/B2 -> 15760.11 | K2: =G2/B2 -> 4371.0903
A3: B. Chen | B3: =COUNTIF(clean_data!T:T,sales!A3) -> 48 | C3: =_xlfn.MINIFS(clean_data!F:F,clean_data!T:T,sales!A3) -> 44928 | D3: =_xlfn.MAXIFS(clean_data!F:F,clean_data!T:T,sales!A3) -> 45894 | E3: =DATEDIF(C3,D3,"m") -> 31 | F3: =SUMIF(clean_data!T:T,sales!A3,clean_data!AM:AM) -> 893735.66 | G3: =SUMIF(clean_data!T:T,sales!A3,clean_data!AN:AN) -> 315969.97 | H3: =AVERAGEIF(Table1[Salesperson],sales!A3,clean_data!AA:AA) -> 0.1291875 | I3: =B3/E3 -> 1.5483871 | J3: =F3/B3 -> 18619.493 | K3: =G3/B3 -> 6582.7077
A4: G. Dubois | B4: =COUNTIF(clean_data!T:T,sales!A4) -> 30 | C4: =_xlfn.MINIFS(clean_data!F:F,clean_data!T:T,sales!A4) -> 44945 | D4: =_xlfn.MAXIFS(clean_data!F:F,clean_data!T:T,sales!A4) -> 45858 | E4: =DATEDIF(C4,D4,"m") -> 30 | F4: =SUMIF(clean_data!T:T,sales!A4,clean_data!AM:AM) -> 510653.71 | G4: =SUMIF(clean_data!T:T,sales!A4,clean_data!AN:AN) -> 172441.87 | H4: =AVERAGEIF(Table1[Salesperson],sales!A4,clean_data!AA:AA) -> 0.12106667 | I4: =B4/E4 -> 1 | J4: =F4/B4 -> 17021.79 | K4: =G4/B4 -> 5748.0624
A5: A. Patel | B5: =COUNTIF(clean_data!T:T,sales!A5) -> 48 | C5: =_xlfn.MINIFS(clean_data!F:F,clean_data!T:T,sales!A5) -> 44933 | D5: =_xlfn.MAXIFS(clean_data!F:F,clean_data!T:T,sales!A5) -> 45915 | E5: =DATEDIF(C5,D5,"m") -> 32 | F5: =SUMIF(clean_data!T:T,sales!A5,clean_data!AM:AM) -> 1005389.1 | G5: =SUMIF(clean_data!T:T,sales!A5,clean_data!AN:AN) -> 337634.71 | H5: =AVERAGEIF(Table1[Salesperson],sales!A5,clean_data!AA:AA) -> 0.11516667 | I5: =B5/E5 -> 1.5 | J5: =F5/B5 -> 20945.606 | K5: =G5/B5 -> 7034.0564
A6: L. Okafor | B6: =COUNTIF(clean_data!T:T,sales!A6) -> 49 | C6: =_xlfn.MINIFS(clean_data!F:F,clean_data!T:T,sales!A6) -> 44962 | D6: =_xlfn.MAXIFS(clean_data!F:F,clean_data!T:T,sales!A6) -> 45915 | E6: =DATEDIF(C6,D6,"m") -> 31 | F6: =SUMIF(clean_data!T:T,sales!A6,clean_data!AM:AM) -> 904189.82 | G6: =SUMIF(clean_data!T:T,sales!A6,clean_data!AN:AN) -> 285453.56 | H6: =AVERAGEIF(Table1[Salesperson],sales!A6,clean_data!AA:AA) -> 0.10359184 | I6: =B6/E6 -> 1.5806452 | J6: =F6/B6 -> 18452.854 | K6: =G6/B6 -> 5825.5829
A7: F. Müller | B7: =COUNTIF(clean_data!T:T,sales!A7) -> 51 | C7: =_xlfn.MINIFS(clean_data!F:F,clean_data!T:T,sales!A7) -> 44948 | D7: =_xlfn.MAXIFS(clean_data!F:F,clean_data!T:T,sales!A7) -> 45912 | E7: =DATEDIF(C7,D7,"m") -> 31 | F7: =SUMIF(clean_data!T:T,sales!A7,clean_data!AM:AM) -> 812637.17 | G7: =SUMIF(clean_data!T:T,sales!A7,clean_data!AN:AN) -> 251733.01 | H7: =AVERAGEIF(Table1[Salesperson],sales!A7,clean_data!AA:AA) -> 0.11254902 | I7: =B7/E7 -> 1.6451613 | J7: =F7/B7 -> 15934.062 | K7: =G7/B7 -> 4935.9414
A8: M. Rossi | B8: =COUNTIF(clean_data!T:T,sales!A8) -> 48 | C8: =_xlfn.MINIFS(clean_data!F:F,clean_data!T:T,sales!A8) -> 44938 | D8: =_xlfn.MAXIFS(clean_data!F:F,clean_data!T:T,sales!A8) -> 45902 | E8: =DATEDIF(C8,D8,"m") -> 31 | F8: =SUMIF(clean_data!T:T,sales!A8,clean_data!AM:AM) -> 966298.99 | G8: =SUMIF(clean_data!T:T,sales!A8,clean_data!AN:AN) -> 302657.06 | H8: =AVERAGEIF(Table1[Salesperson],sales!A8,clean_data!AA:AA) -> 0.11735417 | I8: =B8/E8 -> 1.5483871 | J8: =F8/B8 -> 20131.229 | K8: =G8/B8 -> 6305.3554
A9: O. Wang | B9: =COUNTIF(clean_data!T:T,sales!A9) -> 37 | C9: =_xlfn.MINIFS(clean_data!F:F,clean_data!T:T,sales!A9) -> 44941 | D9: =_xlfn.MAXIFS(clean_data!F:F,clean_data!T:T,sales!A9) -> 45910 | E9: =DATEDIF(C9,D9,"m") -> 31 | F9: =SUMIF(clean_data!T:T,sales!A9,clean_data!AM:AM) -> 647724.9 | G9: =SUMIF(clean_data!T:T,sales!A9,clean_data!AN:AN) -> 185219.44 | H9: =AVERAGEIF(Table1[Salesperson],sales!A9,clean_data!AA:AA) -> 0.12578378 | I9: =B9/E9 -> 1.1935484 | J9: =F9/B9 -> 17506.078 | K9: =G9/B9 -> 5005.9307
A10: H. Kim | B10: =COUNTIF(clean_data!T:T,sales!A10) -> 47 | C10: =_xlfn.MINIFS(clean_data!F:F,clean_data!T:T,sales!A10) -> 44939 | D10: =_xlfn.MAXIFS(clean_data!F:F,clean_data!T:T,sales!A10) -> 45855 | E10: =DATEDIF(C10,D10,"m") -> 30 | F10: =SUMIF(clean_data!T:T,sales!A10,clean_data!AM:AM) -> 727151.52 | G10: =SUMIF(clean_data!T:T,sales!A10,clean_data!AN:AN) -> 144057.31 | H10: =AVERAGEIF(Table1[Salesperson],sales!A10,clean_data!AA:AA) -> 0.11246809 | I10: =B10/E10 -> 1.5666667 | J10: =F10/B10 -> 15471.309 | K10: =G10/B10 -> 3065.0491
A11: C. Otieno | B11: =COUNTIF(clean_data!T:T,sales!A11) -> 37 | C11: =_xlfn.MINIFS(clean_data!F:F,clean_data!T:T,sales!A11) -> 44980 | D11: =_xlfn.MAXIFS(clean_data!F:F,clean_data!T:T,sales!A11) -> 45908 | E11: =DATEDIF(C11,D11,"m") -> 30 | F11: =SUMIF(clean_data!T:T,sales!A11,clean_data!AM:AM) -> 685111.86 | G11: =SUMIF(clean_data!T:T,sales!A11,clean_data!AN:AN) -> 225695.02 | H11: =AVERAGEIF(Table1[Salesperson],sales!A11,clean_data!AA:AA) -> 0.13578378 | I11: =B11/E11 -> 1.2333333 | J11: =F11/B11 -> 18516.537 | K11: =G11/B11 -> 6099.8654
A12: J. Njeri | B12: =COUNTIF(clean_data!T:T,sales!A12) -> 50 | C12: =_xlfn.MINIFS(clean_data!F:F,clean_data!T:T,sales!A12) -> 45012 | D12: =_xlfn.MAXIFS(clean_data!F:F,clean_data!T:T,sales!A12) -> 45911 | E12: =DATEDIF(C12,D12,"m") -> 29 | F12: =SUMIF(clean_data!T:T,sales!A12,clean_data!AM:AM) -> 802384.66 | G12: =SUMIF(clean_data!T:T,sales!A12,clean_data!AN:AN) -> 273113.11 | H12: =AVERAGEIF(Table1[Salesperson],sales!A12,clean_data!AA:AA) -> 0.11814 | I12: =B12/E12 -> 1.7241379 | J12: =F12/B12 -> 16047.693 | K12: =G12/B12 -> 5462.2622
A13: K. Singh | B13: =COUNTIF(clean_data!T:T,sales!A13) -> 44 | C13: =_xlfn.MINIFS(clean_data!F:F,clean_data!T:T,sales!A13) -> 44972 | D13: =_xlfn.MAXIFS(clean_data!F:F,clean_data!T:T,sales!A13) -> 45901 | E13: =DATEDIF(C13,D13,"m") -> 30 | F13: =SUMIF(clean_data!T:T,sales!A13,clean_data!AM:AM) -> 883348.13 | G13: =SUMIF(clean_data!T:T,sales!A13,clean_data!AN:AN) -> 278762.27 | H13: =AVERAGEIF(Table1[Salesperson],sales!A13,clean_data!AA:AA) -> 0.14031818 | I13: =B13/E13 -> 1.4666667 | J13: =F13/B13 -> 20076.094 | K13: =G13/B13 -> 6335.5061
... A16: N. Brown | B16: =COUNTIF(clean_data!T:T,sales!A16) -> 32 | C16: =_xlfn.MINIFS(clean_data!F:F,clean_data!T:T,sales!A16) -> 44953 | D16: =_xlfn.MAXIFS(clean_data!F:F,clean_data!T:T,sales!A16) -> 45914 | E16: =DATEDIF(C16,D16,"m") -> 31 | F16: =SUMIF(clean_data!T:T,sales!A16,clean_data!AM:AM) -> 388325.14 | G16: =SUMIF(clean_data!T:T,sales!A16,clean_data!AN:AN) -> 110646.46 | H16: =AVERAGEIF(Table1[Salesperson],sales!A16,clean_data!AA:AA) -> 0.09959375 | I16: =B16/E16 -> 1.0322581 | J16: =F16/B16 -> 12135.161 | K16: =G16/B16 -> 3457.7018
A19: Row Labels | B19: Revenue
A20: 1 | B20: 701241.31
A21: 2 | B21: 962551.41
A22: 3 | B22: 798978.3
A23: 4 | B23: 947246.58
A24: 5 | B24: 1262173.9
A25: 6 | B25: 1252428.2
A26: 7 | B26: 1313062.3
A27: 8 | B27: 1089608.8
A28: 9 | B28: 661159.43
A29: 10 | B29: 658776.06
A30: 11 | B30: 543953.69
A31: 12 | B31: 734787.61
A32: Grand Total | B32: 10925968

Sheet Quantiles
A1: Quartile | B1: value
A2: Low | B2: =_xlfn.PERCENTILE.INC(clean_data!Y:Y,0.33) -> 816.0801
A3: Medium | B3: =_xlfn.PERCENTILE.INC(clean_data!Y:Y,0.67) -> 1640.0575
A4: High

Sheet Cohort_analysis
A3: Sum of gross_revenue | B3: cohorts
A4: Row Labels | B4: 0 | C4: 1 | D4: 2 | E4: 3 | F4: 4 | G4: 5 | H4: 6 | I4: 7 | J4: 8 | K4: 9 | L4: 10 | M4: 11 | N4: 12 | O4: 13 | P4: 14 | Q4: 15 | R4: 16 | S4: 17 | T4: 18 | U4: 19 | V4: 20 | W4: 21 | X4: 22 | Y4: 23 | Z4: 24 | AA4: 25 | AB4: 26 | AC4: 27 | AD4: 28 | AE4: 29 | AF4: 30 | AG4: 31 | AH4: 32 | AI4: Grand Total
A5: Brazil | B5: 26695.838 | C5: 24523.007 | D5: 12248.676 | E5: 27194.152 | F5: 46991.747 | G5: 93430.735 | H5: 37330.003 | I5: 7071.6331 | J5: 16213.633 | K5: 24161.263 | L5: 61471.697 | M5: 8567.3925 | N5: 39239.198 | O5: 110.1492 | P5: 57491.063 | Q5: 9469.7678 | S5: 52596.047 | T5: 41358.42 | U5: 85419.018 | W5: 11939.431 | Y5: 22987.328 | Z5: 70563.592 | AA5: 15158.393 | AB5: 70019.054 | AC5: 67158.245 | AE5: 38096.184 | AF5: 45754.744 | AG5: 24172.045 | AI5: 1037432.5
A6: Canada | B6: 4141.76 | C6: 26150.364 | D6: 17453.344 | E6: 15618.845 | G6: 46226.12 | H6: 29536.716 | I6: 52625.804 | J6: 15530.93 | K6: 27756.432 | M6: 14466.951 | N6: 19139.594 | O6: 9774.3888 | P6: 21931.504 | R6: 17930.495 | S6: 55516.604 | T6: 79082.507 | U6: 7466.3064 | V6: 64160.245 | X6: 60697.471 | Y6: 20713.04 | AA6: 8128.5187 | AC6: 7901.5042 | AD6: 76122.593 | AE6: 5335.5655 | AF6: 141645.57 | AG6: 24972.288 | AH6: 12597.522 | AI6: 882622.98
